Workbook
Name Fokusområden: #REF!
Name Q: [1]Лист2!$B$1:$B$5
Name Z: [3]DFMEA!$A$1:$IV$10
Name Статус: [4]Лист1!$B$2:$B$5
Name Статус: [1]Лист2!$B$1:$B$5

Sheet Revision History
B3: Internal Audit Plan (03 Years Calendar)
B4: Plant: | C4: Kubikenborg Aluminium AB
B5: Process: | C5: 2.6 Quality Management
B6: Revision No. | C6: 9
B7: Latest revision date: | C7: 46058
B8: Full name of resp. person: | C8: Regina De Paula
B9: 1st release date: | C9: 44704
B10: Revision History
B11: Revision date | C11: Revision description | D11: Revision No. | E11: Lates update by | F11: Comments
B12: 45729 | C12: Added Row for Plan and Fact + Added Revision History sheet | D12: 2 | E12: Regina P.
B13: 45743 | C13: Moved Supplier Audit from Sep/25 to Apr/25, since we had Anodes claim | D13: 3 | E13: Regina P.
B14: 45769 | C14: Moved ISO 14001 Audit from week 17 to week 20, Because Environmental manager is in sick leave. | D14: 4 | E14: Mehdi H
B15: 45883 | C15: Extended EcoVadis Assessment until Nov/25 | D15: 5 | E15: Regina P.
B16: 45918 | C16: Updated links for reports (Facts) | D16: 6 | E16: Regina P.
B17: 45945 | C17: Added Yearly update checklist sheet | D17: 7 | E17: Mehdi H | F17: After IATF External Audit
B18: 46036 | C18: Added CO2 audit plan | D18: 8 | E18: Mehdi H | F18: Environment personal sick
B19: 46058 | C19: Revised plan and inserted "external" days for ASI and IATF 16949 | D19: 9 | E19: Regina P.

Sheet Calendar
B2: Internal Audit Plan > Calendar | AA2: x | AB2: Fact | AD2: x | AE2: Antecipated
AA3: x | AB3: Plan
B5: Year | C5: Internal Audit | E5: Jan | I5: Feb | M5: Mar | R5: Apr | V5: May | AA5: Jun | AE5: Jul | AI5: Aug | AN5: Sep | AR5: Oct | AW5: Nov | BA5: Dec
E6: 1 | F6: 2 | G6: =F6+1 -> 3 | H6: =G6+1 -> 4 | I6: =H6+1 -> 5 | J6: =I6+1 -> 6 | K6: =J6+1 -> 7 | L6: =K6+1 -> 8 | M6: =L6+1 -> 9 | N6: =M6+1 -> 10 | ... BD6: =BC6+1 -> 52
B7: 2023 | C7: ISO 9001 | AO7: X
C8: ISO 14001
C9: IATF 16949 | X9: X | AO9: X
C10: VDA 6.3 Process | Q10: X | AP10: X
C11: VDA 6.5 Product | L11: X | N11: X | T11: X | AB11: X | AC11: X | AQ11: X | BC11: X
C12: Supplier | AR12: X | AS12: X
C13: CO2 Emissions | Q13: X
B15: Year | C15: Internal Audit | E15: Jan | I15: Feb | M15: Mar | R15: Apr | V15: May | AA15: Jun | AE15: Jul | AI15: Aug | AN15: Sep | AR15: Oct | AW15: Nov | BA15: Dec
E16: 1 | F16: 2 | G16: =F16+1 -> 3 | H16: =G16+1 -> 4 | I16: =H16+1 -> 5 | J16: =I16+1 -> 6 | K16: =J16+1 -> 7 | L16: =K16+1 -> 8 | M16: =L16+1 -> 9 | N16: =M16+1 -> 10 | ... BD16: =BC16+1 -> 52
B17: 2024 | C17: ISO 9001 | Q17: X
C18: ISO 14001
C19: IATF 16949 | AP19: X
C20: VDA 6.3 Process | K20: X | V20: X | BB20: X
C21: VDA 6.5 Product | L21: X | S21: X | V21: X | W21: X | X21: X
C22: Supplier
C23: CO2 Emissions | T23: X
B25: Year | C25: Internal Audit | D25: Status | E25: Jan | I25: Feb | N25: Mar | R25: Apr | V25: May | AA25: Jun | AE25: Jul | AI25: Aug | AN25: Sep | AR25: Oct | AW25: Nov | BA25: Dec
E26: 1 | F26: 2 | G26: =F26+1 -> 3 | H26: =G26+1 -> 4 | I26: =H26+1 -> 5 | J26: =I26+1 -> 6 | K26: =J26+1 -> 7 | L26: =K26+1 -> 8 | M26: =L26+1 -> 9 | N26: =M26+1 -> 10 | ... BD26: =BC26+1 -> 52
B27: 2025 | C27: EcoVadis Assessment | D27: Plan | K27: x | AZ27: x
D28: Fact | K28: x | AZ28: x
C29: ASI | D29: Plan
D30: Fact
C31: ISO 9001 | D31: Plan | AK31: x
D32: Fact | AK32: x
C33: ISO 14001 | D33: Plan | X33: x
D34: Fact | X34: x
C35: IATF 16949 | D35: Plan | AK35: x | AR35: x
D36: Fact | AK36: x | AR36: x
C37: VDA 6.3 Process | D37: Plan | N37: x
D38: Fact | N38: x | P38: x
C39: VDA 6.3 (Moldshop) | D39: Plan | J39: x
D40: Fact | M40: x
C41: VDA 6.5 Product | D41: Plan | N41: x | U41: x | AA41: x | BB41: x
D42: Fact | N42: x | P42: x | U42: x | AA42: x | BB42: x
C43: Supplier | D43: Plan | Z43: x
D44: Fact | Z44: x
...

Sheet IATF 16949
C2: IATF 16949 Internal Audits
B5: VDA | C5: Month | D5: Charge number | E5: Result
B6: 6.3 | C6: feb.21 | D6: 402295 | E6: 0.99
B7: 6.3 | C7: may. 07 | D7: 404095 | E7: 0.99
B11: VDA
B12: 6.5 | C12: feb. 21 | E12: 0
B13: 6.5 | C13: apr.09 | D13: 404095 | E13: 0
B14: 6.5 | C14: may.08 | D14: 405107 | E14: 100
B15: 6.5 | C15: may.08 | D15: 405102 | E15: 10

Sheet Data
C2: Internal Audit Calendar Plan | 2026
P3: Total Audit Plan 2026
B4: Do not delete! | C4: 01 Jan | D4: 02 Feb | E4: 03 Mar | F4: 04 Apr | G4: 05 May | H4: 06 Jun | I4: 07 Jul | J4: 08 Aug | K4: 09 Sep | L4: 10 Oct | M4: 11 Nov | N4: 12 Dec | P4: Audit Plan 2026 | Q4: Internal Audits | R4: External Audits
B5: EcoVadis Assessment | C5: =IF(COUNTA(Calendar!E50:H50)=0,"",$B$5) | D5: =IF(COUNTA(Calendar!I50:L50)=0,"",$B$5) -> EcoVadis Assessment | E5: =IF(COUNTA(Calendar!M50:Q50)=0,"",$B$5) | F5: =IF(COUNTA(Calendar!R50:U50)=0,"",$B$5) | G5: =IF(COUNTA(Calendar!V50:Z50)=0,"",$B$5) | H5: =IF(COUNTA(Calendar!AA50:AD50)=0,"",$B$5) | I5: =IF(COUNTA(Calendar!AE50:AH50)=0,"",$B$5) | J5: =IF(COUNTA(Calendar!AI50:AM50)=0,"",$B$5) -> EcoVadis Assessment | K5: =IF(COUNTA(Calendar!AN50:AQ50)=0,"",$B$5) | L5: =IF(COUNTA(Calendar!AR50:AV50)=0,"",$B$5) | M5: =IF(COUNTA(Calendar!AW50:AZ50)=0,"",$B$5) | N5: =IF(COUNTA(Calendar!BA50:BD50)=0,"",$B$5) | P5: EcoVadis Assessment | Q5: =IF(Q21="","",Q21) -> 5 | R5: =IF(R21="","",R21)
B6: ASI | C6: =IF(COUNTA(Calendar!E52:H52)=0,"",$B$6) | D6: =IF(COUNTA(Calendar!I52:L52)=0,"",$B$6) | E6: =IF(COUNTA(Calendar!M52:Q52)=0,"",$B$6) -> ASI | F6: =IF(COUNTA(Calendar!R52:U52)=0,"",$B$6) | G6: =IF(COUNTA(Calendar!V52:Z52)=0,"",$B$6) | H6: =IF(COUNTA(Calendar!AA52:AD52)=0,"",$B$6) | I6: =IF(COUNTA(Calendar!AE52:AH52)=0,"",$B$6) | J6: =IF(COUNTA(Calendar!AI52:AM52)=0,"",$B$6) -> ASI | K6: =IF(COUNTA(Calendar!AN52:AQ52)=0,"",$B$6) | L6: =IF(COUNTA(Calendar!AR52:AV52)=0,"",$B$6) | M6: =IF(COUNTA(Calendar!AW52:AZ52)=0,"",$B$6) | N6: =IF(COUNTA(Calendar!BA52:BD52)=0,"",$B$6) | P6: ASI | Q6: =IF(Q22="","",Q22) -> 2 | R6: =IF(R22="","",R22) -> 1
B7: ISO 9001 | C7: =IF(COUNTA(Calendar!E54:H54)=0,"",$B$7) | D7: =IF(COUNTA(Calendar!I54:L54)=0,"",$B$7) | E7: =IF(COUNTA(Calendar!M54:Q54)=0,"",$B$7) | F7: =IF(COUNTA(Calendar!R54:U54)=0,"",$B$7) | G7: =IF(COUNTA(Calendar!W54:Z54)=0,"",$B$7) -> ISO 9001 | H7: =IF(COUNTA(Calendar!AA54:AD54)=0,"",$B$7) | I7: =IF(COUNTA(Calendar!AE54:AH54)=0,"",$B$7) | J7: =IF(COUNTA(Calendar!AI54:AM54)=0,"",$B$7) | K7: =IF(COUNTA(Calendar!AN54:AQ54)=0,"",$B$7) | L7: =IF(COUNTA(Calendar!AR54:AV54)=0,"",$B$7) | M7: =IF(COUNTA(Calendar!AW54:AZ54)=0,"",$B$7) | N7: =IF(COUNTA(Calendar!BA54:BD54)=0,"",$B$7) | P7: ISO 9001 | Q7: =IF(Q23="","",Q23) -> 1 | R7: =IF(R23="","",R23)
B8: ISO 14001 | C8: =IF(COUNTA(Calendar!E56:H56)=0,"",$B$8) | D8: =IF(COUNTA(Calendar!I56:L56)=0,"",$B$8) | E8: =IF(COUNTA(Calendar!M56:Q56)=0,"",$B$8) | F8: =IF(COUNTA(Calendar!R56:U56)=0,"",$B$8) | G8: =IF(COUNTA(Calendar!V56:Z56)=0,"",$B$8) | H8: =IF(COUNTA(Calendar!AA56:AD56)=0,"",$B$8) | I8: =IF(COUNTA(Calendar!AE56:AH56)=0,"",$B$8) | J8: =IF(COUNTA(Calendar!AI56:AM56)=0,"",$B$8) | K8: =IF(COUNTA(Calendar!AN56:AQ56)=0,"",$B$8) | L8: =IF(COUNTA(Calendar!AR56:AV56)=0,"",$B$8) | M8: =IF(COUNTA(Calendar!AW56:AZ56)=0,"",$B$8) -> ISO 14001 | N8: =IF(COUNTA(Calendar!BA56:BD56)=0,"",$B$8) | P8: ISO 14001 | Q8: =IF(Q24="","",Q24) -> 1 | R8: =IF(R24="","",R24)
B9: IATF 16949 | C9: =IF(COUNTA(Calendar!E58:H58)=0,"",$B$9) | D9: =IF(COUNTA(Calendar!I58:L58)=0,"",$B$9) | E9: =IF(COUNTA(Calendar!M58:Q58)=0,"",$B$9) -> IATF 16949 | F9: =IF(COUNTA(Calendar!R58:U58)=0,"",$B$9) | G9: =IF(COUNTA(Calendar!V58:Z58)=0,"",$B$9) | H9: =IF(COUNTA(Calendar!AA58:AD58)=0,"",$B$9) | I9: =IF(COUNTA(Calendar!AE58:AH58)=0,"",$B$9) | J9: =IF(COUNTA(Calendar!AI58:AM58)=0,"",$B$9) | K9: =IF(COUNTA(Calendar!AN58:AQ58)=0,"",$B$9) -> IATF 16949 | L9: =IF(COUNTA(Calendar!AR58:AV58)=0,"",$B$9) -> IATF 16949 | M9: =IF(COUNTA(Calendar!AW58:AZ58)=0,"",$B$9) | N9: =IF(COUNTA(Calendar!BA58:BD58)=0,"",$B$9) | P9: IATF 16949 | Q9: =IF(Q25="","",Q25) -> 3 | R9: =IF(R25="","",R25) -> 1
B10: VDA 6.3 Process | C10: =IF(COUNTA(Calendar!E60:H60)=0,"",$B$10) | D10: =IF(COUNTA(Calendar!I60:L60)=0,"",$B$10) | E10: =IF(COUNTA(Calendar!M60:Q60)=0,"",$B$10) | F10: =IF(COUNTA(Calendar!R60:U60)=0,"",$B$10) | G10: =IF(COUNTA(Calendar!V60:Z60)=0,"",$B$10) | H10: =IF(COUNTA(Calendar!AA60:AD60)=0,"",$B$10) -> VDA 6.3 Process | I10: =IF(COUNTA(Calendar!AE60:AH60)=0,"",$B$10) | J10: =IF(COUNTA(Calendar!AI60:AM60)=0,"",$B$10) | K10: =IF(COUNTA(Calendar!AN60:AQ60)=0,"",$B$10) | L10: =IF(COUNTA(Calendar!AR60:AV60)=0,"",$B$10) | M10: =IF(COUNTA(Calendar!AW60:AZ60)=0,"",$B$10) | N10: =IF(COUNTA(Calendar!BA60:BD60)=0,"",$B$10) | P10: VDA 6.3 Process | Q10: =IF(Q26="","",Q26) -> 1 | R10: =IF(R26="","",R26)
B11: VDA 6.3 (Moldshop) | C11: =IF(COUNTA(Calendar!E62:H62)=0,"",$B$11) | D11: =IF(COUNTA(Calendar!I62:L62)=0,"",$B$11) | E11: =IF(COUNTA(Calendar!M62:Q62)=0,"",$B$11) | F11: =IF(COUNTA(Calendar!R62:U62)=0,"",$B$11) -> VDA 6.3 (Moldshop) | G11: =IF(COUNTA(Calendar!V62:Z62)=0,"",$B$11) | H11: =IF(COUNTA(Calendar!AA62:AD62)=0,"",$B$11) | I11: =IF(COUNTA(Calendar!AE62:AH62)=0,"",$B$11) | J11: =IF(COUNTA(Calendar!AI62:AM62)=0,"",$B$11) | K11: =IF(COUNTA(Calendar!AN62:AQ62)=0,"",$B$11) | L11: =IF(COUNTA(Calendar!AR62:AV62)=0,"",$B$11) | M11: =IF(COUNTA(Calendar!AW62:AZ62)=0,"",$B$11) | N11: =IF(COUNTA(Calendar!BA62:BD62)=0,"",$B$11) | P11: VDA 6.3 (Moldshop) | Q11: =IF(Q27="","",Q27) -> 1 | R11: =IF(R27="","",R27)
B12: VDA 6.5 Product | C12: =IF(COUNTA(Calendar!E64:H64)=0,"",$B$12) | D12: =IF(COUNTA(Calendar!I64:M64)=0,"",$B$12) -> VDA 6.5 Product | E12: =IF(COUNTA(Calendar!M64:Q64)=0,"",$B$12) | F12: =IF(COUNTA(Calendar!R64:U64)=0,"",$B$12) | G12: =IF(COUNTA(Calendar!V64:Z64)=0,"",$B$12) | H12: =IF(COUNTA(Calendar!AA64:AD64)=0,"",$B$12) | I12: =IF(COUNTA(Calendar!AE64:AH64)=0,"",$B$12) -> VDA 6.5 Product | J12: =IF(COUNTA(Calendar!AI64:AM64)=0,"",$B$12) | K12: =IF(COUNTA(Calendar!AN64:AQ64)=0,"",$B$12) | L12: =IF(COUNTA(Calendar!AR64:AV64)=0,"",$B$12) | M12: =IF(COUNTA(Calendar!AW64:AZ64)=0,"",$B$12) | N12: =IF(COUNTA(Calendar!BA64:BD64)=0,"",$B$12) -> VDA 6.5 Product | P12: VDA 6.5 Product | Q12: =IF(Q28="","",Q28) -> 3 | R12: =IF(R28="","",R28)
B13: Supplier | C13: =IF(COUNTA(Calendar!E66:H66)=0,"",$B$13) | D13: =IF(COUNTA(Calendar!I66:L66)=0,"",$B$13) | E13: =IF(COUNTA(Calendar!M66:Q66)=0,"",$B$13) | F13: =IF(COUNTA(Calendar!R66:U66)=0,"",$B$13) | G13: =IF(COUNTA(Calendar!V66:Z66)=0,"",$B$13) | H13: =IF(COUNTA(Calendar!AA66:AD66)=0,"",$B$13) | I13: =IF(COUNTA(Calendar!AE66:AH66)=0,"",$B$13) | J13: =IF(COUNTA(Calendar!AI66:AM66)=0,"",$B$13) | K13: =IF(COUNTA(Calendar!AN66:AQ66)=0,"",$B$13) -> Supplier | L13: =IF(COUNTA(Calendar!AR66:AV66)=0,"",$B$13) | M13: =IF(COUNTA(Calendar!AW66:AZ66)=0,"",$B$13) | N13: =IF(COUNTA(Calendar!BA66:BD66)=0,"",$B$13) | P13: Supplier | Q13: =IF(Q29="","",Q29) -> 1 | R13: =IF(R29="","",R29)
B14: CO2 Emissions | C14: =IF(COUNTA(Calendar!E68:H68)=0,"",$B$14) -> CO2 Emissions | D14: =IF(COUNTA(Calendar!I68:L68)=0,"",$B$14) | E14: =IF(COUNTA(Calendar!M68:Q68)=0,"",$B$14) | F14: =IF(COUNTA(Calendar!R68:U68)=0,"",$B$14) | G14: =IF(COUNTA(Calendar!V68:Z68)=0,"",$B$14) | H14: =IF(COUNTA(Calendar!AA68:AD68)=0,"",$B$14) | I14: =IF(COUNTA(Calendar!AE68:AH68)=0,"",$B$14) | J14: =IF(COUNTA(Calendar!AI68:AM68)=0,"",$B$14) | K14: =IF(COUNTA(Calendar!AN68:AQ68)=0,"",$B$14) | L14: =IF(COUNTA(Calendar!AR68:AV68)=0,"",$B$14) | M14: =IF(COUNTA(Calendar!AW68:AZ68)=0,"",$B$14) | N14: =IF(COUNTA(Calendar!BA68:BD68)=0,"",$B$14) | P14: CO2 Emissions | Q14: =IF(Q30="","",Q30) -> 1 | R14: =IF(R30="","",R30)
P15: Total 2025 | Q15: =SUM(Q5:Q14) -> 19 | R15: =SUM(R5:R14) -> 2
P19: 2026 PLAN | T19: 2025 FACT
P20: Type (Standard) | Q20: # Internal Audits | R20: # External Audits | T20: Month | U20: # Internal Audits | V20: # External Audits
P21: EcoVadis Assessment | Q21: =COUNTA(Calendar!E50:BD50) -> 5 | T21: Jan | U21: 1
P22: ASI | Q22: =COUNTA(Calendar!E52:BD52) -> 2 | R22: 1 | T22: Feb | U22: 4
P23: ISO 9001 | Q23: =COUNTA(Calendar!E54:BD54) -> 1 | T23: Mar | U23: 4
P24: ISO 14001 | Q24: =COUNTA(Calendar!E56:BD56) -> 1 | T24: Apr | U24: 1
P25: IATF 16949 | Q25: =COUNTA(Calendar!E58:BD58) -> 3 | R25: 1 | T25: May | U25: 1 | V25: 1
P26: VDA 6.3 Process | Q26: =COUNTA(Calendar!E60:BD60) -> 1 | T26: Jun | U26: 1
P27: VDA 6.3 Process (Moldshop) | Q27: =COUNTA(Calendar!E62:BD62) -> 1 | T27: Jul | U27: =COUNTA(Calendar!AE27:AH46) -> 0
P28: VDA 6.5 Product | Q28: =COUNTA(Calendar!E64:BD64) -> 3 | T28: Aug | U28: =COUNTA(Calendar!AI27:AM46) -> 4
P29: Supplier | Q29: =COUNTA(Calendar!E66:BD66) -> 1 | T29: Sep | U29: =COUNTA(Calendar!AN27:AQ46) -> 0
P30: CO2 Emissions | Q30: =COUNTA(Calendar!E68:BD68) -> 1 | T30: Oct | U30: =COUNTA(Calendar!AR27:AV46) -> 2 | V30: 1
P31: Total | Q31: =SUM(Q21:Q30) -> 19 | R31: =SUM(R21:R30) -> 2 | T31: Nov | U31: =COUNTA(Calendar!AW27:AZ46) -> 2
R32: *Manual input | T32: Dec | U32: =COUNTA(Calendar!BA27:BD46) -> 2
T33: Total | U33: =SUM(U21:U32) -> 22 | V33: =SUM(V21:V32) -> 2
V34: *Manual input

Sheet Yearly update check list 
B3: Yearly update check list for audit plan/competence matrix
D5: 2025 | F5: 2026 | H5: 2027
B6: Audit criteria | D6: Date | E6: Status | F6: Date | G6: Status | H6: Date | I6: Status
B7: Competence Matrix | C7: ISO 9001 / ISO 14001 / IATF 16949 (QMS Auditor) | D7: 45698 | E7: Updated | F7: 45671 | G7: Updated
C8: Second Part Auditor (Suppliers) | D8: 45698 | E8: Updated | F8: 45671 | G8: Updated
C9: Process Auditor VDA 6.3 | D9: 45698 | E9: Updated | F9: 45671 | G9: Updated
C10: Product Auditor VDA 6.5 | D10: 45698 | E10: Updated | F10: 45671 | G10: Updated
C11: Second Part Auditor (Suppliers) | D11: 45698 | E11: Updated | F11: 45671 | G11: Updated
B12: Participation | C12: Status of internal auditor | D12: 45903 | E12: Updated | F12: 45671 | G12: Updated
B13: Qualification status | C13: List of Internal Auditors | D13: 45698 | E13: Updated | F13: 45671 | G13: Updated
B14: Calender | C14: Internal audit calender | D14: 45698 | E14: Updated | F14: 45671 | G14: Updated
